2022-05-08 13:18:57,053 django.utils.autoreload INFO     Watching for file changes with StatReloader
2022-05-08 13:20:22,940 django.utils.autoreload INFO     /home/dz/PycharmProjects/new_test_work/new_test_work/urls.py changed, reloading.
2022-05-08 13:20:23,256 django.utils.autoreload INFO     Watching for file changes with StatReloader
2022-05-08 13:20:24,013 django.request ERROR    Internal Server Error: /
Traceback (most recent call last):
  File "/home/dz/PycharmProjects/new_test_work/venv/lib/python3.10/site-packages/django/contrib/sessions/backends/base.py", line 187, in _get_session
    return self._session_cache
AttributeError: 'SessionStore' object has no attribute '_session_cache'

During handling of the above exception, another exception occurred:

Traceback (most recent call last):
  File "/home/dz/PycharmProjects/new_test_work/venv/lib/python3.10/site-packages/django/db/backends/utils.py", line 89, in _execute
    return self.cursor.execute(sql, params)
  File "/home/dz/PycharmProjects/new_test_work/venv/lib/python3.10/site-packages/django/db/backends/sqlite3/base.py", line 477, in execute
    return Database.Cursor.execute(self, query, params)
sqlite3.OperationalError: no such table: django_session

The above exception was the direct cause of the following exception:

Traceback (most recent call last):
  File "/home/dz/PycharmProjects/new_test_work/venv/lib/python3.10/site-packages/django/core/handlers/exception.py", line 55, in inner
    response = get_response(request)
  File "/home/dz/PycharmProjects/new_test_work/venv/lib/python3.10/site-packages/django/core/handlers/base.py", line 197, in _get_response
    response = wrapped_callback(request, *callback_args, **callback_kwargs)
  File "/home/dz/PycharmProjects/new_test_work/venv/lib/python3.10/site-packages/django/contrib/auth/decorators.py", line 22, in _wrapped_view
    if test_func(request.user):
  File "/home/dz/PycharmProjects/new_test_work/venv/lib/python3.10/site-packages/django/contrib/auth/decorators.py", line 51, in <lambda>
    lambda u: u.is_authenticated,
  File "/home/dz/PycharmProjects/new_test_work/venv/lib/python3.10/site-packages/django/utils/functional.py", line 258, in inner
    self._setup()
  File "/home/dz/PycharmProjects/new_test_work/venv/lib/python3.10/site-packages/django/utils/functional.py", line 398, in _setup
    self._wrapped = self._setupfunc()
  File "/home/dz/PycharmProjects/new_test_work/venv/lib/python3.10/site-packages/django/contrib/auth/middleware.py", line 25, in <lambda>
    request.user = SimpleLazyObject(lambda: get_user(request))
  File "/home/dz/PycharmProjects/new_test_work/venv/lib/python3.10/site-packages/django/contrib/auth/middleware.py", line 11, in get_user
    request._cached_user = auth.get_user(request)
  File "/home/dz/PycharmProjects/new_test_work/venv/lib/python3.10/site-packages/django/contrib/auth/__init__.py", line 191, in get_user
    user_id = _get_user_session_key(request)
  File "/home/dz/PycharmProjects/new_test_work/venv/lib/python3.10/site-packages/django/contrib/auth/__init__.py", line 60, in _get_user_session_key
    return get_user_model()._meta.pk.to_python(request.session[SESSION_KEY])
  File "/home/dz/PycharmProjects/new_test_work/venv/lib/python3.10/site-packages/django/contrib/sessions/backends/base.py", line 53, in __getitem__
    return self._session[key]
  File "/home/dz/PycharmProjects/new_test_work/venv/lib/python3.10/site-packages/django/contrib/sessions/backends/base.py", line 192, in _get_session
    self._session_cache = self.load()
  File "/home/dz/PycharmProjects/new_test_work/venv/lib/python3.10/site-packages/django/contrib/sessions/backends/db.py", line 42, in load
    s = self._get_session_from_db()
  File "/home/dz/PycharmProjects/new_test_work/venv/lib/python3.10/site-packages/django/contrib/sessions/backends/db.py", line 32, in _get_session_from_db
    return self.model.objects.get(
  File "/home/dz/PycharmProjects/new_test_work/venv/lib/python3.10/site-packages/django/db/models/manager.py", line 85, in manager_method
    return getattr(self.get_queryset(), name)(*args, **kwargs)
  File "/home/dz/PycharmProjects/new_test_work/venv/lib/python3.10/site-packages/django/db/models/query.py", line 492, in get
    num = len(clone)
  File "/home/dz/PycharmProjects/new_test_work/venv/lib/python3.10/site-packages/django/db/models/query.py", line 302, in __len__
    self._fetch_all()
  File "/home/dz/PycharmProjects/new_test_work/venv/lib/python3.10/site-packages/django/db/models/query.py", line 1507, in _fetch_all
    self._result_cache = list(self._iterable_class(self))
  File "/home/dz/PycharmProjects/new_test_work/venv/lib/python3.10/site-packages/django/db/models/query.py", line 57, in __iter__
    results = compiler.execute_sql(
  File "/home/dz/PycharmProjects/new_test_work/venv/lib/python3.10/site-packages/django/db/models/sql/compiler.py", line 1361, in execute_sql
    cursor.execute(sql, params)
  File "/home/dz/PycharmProjects/new_test_work/venv/lib/python3.10/site-packages/django/db/backends/utils.py", line 103, in execute
    return super().execute(sql, params)
  File "/home/dz/PycharmProjects/new_test_work/venv/lib/python3.10/site-packages/django/db/backends/utils.py", line 67, in execute
    return self._execute_with_wrappers(
  File "/home/dz/PycharmProjects/new_test_work/venv/lib/python3.10/site-packages/django/db/backends/utils.py", line 80, in _execute_with_wrappers
    return executor(sql, params, many, context)
  File "/home/dz/PycharmProjects/new_test_work/venv/lib/python3.10/site-packages/django/db/backends/utils.py", line 84, in _execute
    with self.db.wrap_database_errors:
  File "/home/dz/PycharmProjects/new_test_work/venv/lib/python3.10/site-packages/django/db/utils.py", line 91, in __exit__
    raise dj_exc_value.with_traceback(traceback) from exc_value
  File "/home/dz/PycharmProjects/new_test_work/venv/lib/python3.10/site-packages/django/db/backends/utils.py", line 89, in _execute
    return self.cursor.execute(sql, params)
  File "/home/dz/PycharmProjects/new_test_work/venv/lib/python3.10/site-packages/django/db/backends/sqlite3/base.py", line 477, in execute
    return Database.Cursor.execute(self, query, params)
django.db.utils.OperationalError: no such table: django_session
2022-05-08 13:20:24,013 django.request ERROR    Internal Server Error: /
Traceback (most recent call last):
  File "/home/dz/PycharmProjects/new_test_work/venv/lib/python3.10/site-packages/django/contrib/sessions/backends/base.py", line 187, in _get_session
    return self._session_cache
AttributeError: 'SessionStore' object has no attribute '_session_cache'

During handling of the above exception, another exception occurred:

Traceback (most recent call last):
  File "/home/dz/PycharmProjects/new_test_work/venv/lib/python3.10/site-packages/django/db/backends/utils.py", line 89, in _execute
    return self.cursor.execute(sql, params)
  File "/home/dz/PycharmProjects/new_test_work/venv/lib/python3.10/site-packages/django/db/backends/sqlite3/base.py", line 477, in execute
    return Database.Cursor.execute(self, query, params)
sqlite3.OperationalError: no such table: django_session

The above exception was the direct cause of the following exception:

Traceback (most recent call last):
  File "/home/dz/PycharmProjects/new_test_work/venv/lib/python3.10/site-packages/django/core/handlers/exception.py", line 55, in inner
    response = get_response(request)
  File "/home/dz/PycharmProjects/new_test_work/venv/lib/python3.10/site-packages/django/core/handlers/base.py", line 197, in _get_response
    response = wrapped_callback(request, *callback_args, **callback_kwargs)
  File "/home/dz/PycharmProjects/new_test_work/venv/lib/python3.10/site-packages/django/contrib/auth/decorators.py", line 22, in _wrapped_view
    if test_func(request.user):
  File "/home/dz/PycharmProjects/new_test_work/venv/lib/python3.10/site-packages/django/contrib/auth/decorators.py", line 51, in <lambda>
    lambda u: u.is_authenticated,
  File "/home/dz/PycharmProjects/new_test_work/venv/lib/python3.10/site-packages/django/utils/functional.py", line 258, in inner
    self._setup()
  File "/home/dz/PycharmProjects/new_test_work/venv/lib/python3.10/site-packages/django/utils/functional.py", line 398, in _setup
    self._wrapped = self._setupfunc()
  File "/home/dz/PycharmProjects/new_test_work/venv/lib/python3.10/site-packages/django/contrib/auth/middleware.py", line 25, in <lambda>
    request.user = SimpleLazyObject(lambda: get_user(request))
  File "/home/dz/PycharmProjects/new_test_work/venv/lib/python3.10/site-packages/django/contrib/auth/middleware.py", line 11, in get_user
    request._cached_user = auth.get_user(request)
  File "/home/dz/PycharmProjects/new_test_work/venv/lib/python3.10/site-packages/django/contrib/auth/__init__.py", line 191, in get_user
    user_id = _get_user_session_key(request)
  File "/home/dz/PycharmProjects/new_test_work/venv/lib/python3.10/site-packages/django/contrib/auth/__init__.py", line 60, in _get_user_session_key
    return get_user_model()._meta.pk.to_python(request.session[SESSION_KEY])
  File "/home/dz/PycharmProjects/new_test_work/venv/lib/python3.10/site-packages/django/contrib/sessions/backends/base.py", line 53, in __getitem__
    return self._session[key]
  File "/home/dz/PycharmProjects/new_test_work/venv/lib/python3.10/site-packages/django/contrib/sessions/backends/base.py", line 192, in _get_session
    self._session_cache = self.load()
  File "/home/dz/PycharmProjects/new_test_work/venv/lib/python3.10/site-packages/django/contrib/sessions/backends/db.py", line 42, in load
    s = self._get_session_from_db()
  File "/home/dz/PycharmProjects/new_test_work/venv/lib/python3.10/site-packages/django/contrib/sessions/backends/db.py", line 32, in _get_session_from_db
    return self.model.objects.get(
  File "/home/dz/PycharmProjects/new_test_work/venv/lib/python3.10/site-packages/django/db/models/manager.py", line 85, in manager_method
    return getattr(self.get_queryset(), name)(*args, **kwargs)
  File "/home/dz/PycharmProjects/new_test_work/venv/lib/python3.10/site-packages/django/db/models/query.py", line 492, in get
    num = len(clone)
  File "/home/dz/PycharmProjects/new_test_work/venv/lib/python3.10/site-packages/django/db/models/query.py", line 302, in __len__
    self._fetch_all()
  File "/home/dz/PycharmProjects/new_test_work/venv/lib/python3.10/site-packages/django/db/models/query.py", line 1507, in _fetch_all
    self._result_cache = list(self._iterable_class(self))
  File "/home/dz/PycharmProjects/new_test_work/venv/lib/python3.10/site-packages/django/db/models/query.py", line 57, in __iter__
    results = compiler.execute_sql(
  File "/home/dz/PycharmProjects/new_test_work/venv/lib/python3.10/site-packages/django/db/models/sql/compiler.py", line 1361, in execute_sql
    cursor.execute(sql, params)
  File "/home/dz/PycharmProjects/new_test_work/venv/lib/python3.10/site-packages/django/db/backends/utils.py", line 103, in execute
    return super().execute(sql, params)
  File "/home/dz/PycharmProjects/new_test_work/venv/lib/python3.10/site-packages/django/db/backends/utils.py", line 67, in execute
    return self._execute_with_wrappers(
  File "/home/dz/PycharmProjects/new_test_work/venv/lib/python3.10/site-packages/django/db/backends/utils.py", line 80, in _execute_with_wrappers
    return executor(sql, params, many, context)
  File "/home/dz/PycharmProjects/new_test_work/venv/lib/python3.10/site-packages/django/db/backends/utils.py", line 84, in _execute
    with self.db.wrap_database_errors:
  File "/home/dz/PycharmProjects/new_test_work/venv/lib/python3.10/site-packages/django/db/utils.py", line 91, in __exit__
    raise dj_exc_value.with_traceback(traceback) from exc_value
  File "/home/dz/PycharmProjects/new_test_work/venv/lib/python3.10/site-packages/django/db/backends/utils.py", line 89, in _execute
    return self.cursor.execute(sql, params)
  File "/home/dz/PycharmProjects/new_test_work/venv/lib/python3.10/site-packages/django/db/backends/sqlite3/base.py", line 477, in execute
    return Database.Cursor.execute(self, query, params)
django.db.utils.OperationalError: no such table: django_session
2022-05-08 13:21:04,683 django.utils.autoreload INFO     Watching for file changes with StatReloader
